======= Run Summary =======

Run name: "azure_ai_evaluation_evaluators_common_base_eval_asyncevaluatorbase_8jfvpxal_20250221_170053_658842"
Run status: "Completed"
Start time: "2025-02-21 17:00:53.656843+11:00"
Duration: "0:00:09.890340"
Output path: "C:\Users\zhuohangli\.promptflow\.runs\azure_ai_evaluation_evaluators_common_base_eval_asyncevaluatorbase_8jfvpxal_20250221_170053_658842"

Traceback (most recent call last):
  File "C:\Users\zhuohangli\Documents\dev\rag-ai-foundry-sdk-custom-chat-app\.venv\Lib\site-packages\azure\ai\evaluation\_evaluate\_eval_run.py", line 444, in log_artifact
    blob_client.upload_blob(fp, overwrite=True)
  File "C:\Users\zhuohangli\Documents\dev\rag-ai-foundry-sdk-custom-chat-app\.venv\Lib\site-packages\azure\core\tracing\decorator.py", line 116, in wrapper_use_tracer
    return func(*args, **kwargs)
           ^^^^^^^^^^^^^^^^^^^^^
  File "C:\Users\zhuohangli\Documents\dev\rag-ai-foundry-sdk-custom-chat-app\.venv\Lib\site-packages\azure\storage\blob\_blob_client.py", line 605, in upload_blob
    return upload_block_blob(**options)
           ^^^^^^^^^^^^^^^^^^^^^^^^^^^^
  File "C:\Users\zhuohangli\Documents\dev\rag-ai-foundry-sdk-custom-chat-app\.venv\Lib\site-packages\azure\storage\blob\_upload_helpers.py", line 197, in upload_block_blob
    process_storage_error(error)
  File "C:\Users\zhuohangli\Documents\dev\rag-ai-foundry-sdk-custom-chat-app\.venv\Lib\site-packages\azure\storage\blob\_shared\response_handlers.py", line 186, in process_storage_error
    exec("raise error from None")   # pylint: disable=exec-used # nosec
    ^^^^^^^^^^^^^^^^^^^^^^^^^^^^^
  File "<string>", line 1, in <module>
azure.core.exceptions.HttpResponseError: This request is not authorized to perform this operation.
RequestId:e7e033b8-101e-0041-3826-84d520000000
Time:2025-02-21T06:01:09.8305103Z
ErrorCode:AuthorizationFailure
Content: <?xml version="1.0" encoding="utf-8"?><Error><Code>AuthorizationFailure</Code><Message>This request is not authorized to perform this operation.
RequestId:e7e033b8-101e-0041-3826-84d520000000
Time:2025-02-21T06:01:09.8305103Z</Message></Error>

The above exception was the direct cause of the following exception:

Traceback (most recent call last):
  File "C:\Users\zhuohangli\Documents\dev\rag-ai-foundry-sdk-custom-chat-app\evaluate.py", line 59, in <module>
    result = evaluate(
             ^^^^^^^^^
  File "C:\Users\zhuohangli\Documents\dev\rag-ai-foundry-sdk-custom-chat-app\.venv\Lib\site-packages\azure\ai\evaluation\_evaluate\_evaluate.py", line 673, in evaluate
    raise e
  File "C:\Users\zhuohangli\Documents\dev\rag-ai-foundry-sdk-custom-chat-app\.venv\Lib\site-packages\azure\ai\evaluation\_evaluate\_evaluate.py", line 631, in evaluate
    return _evaluate(
           ^^^^^^^^^^
  File "C:\Users\zhuohangli\Documents\dev\rag-ai-foundry-sdk-custom-chat-app\.venv\Lib\site-packages\azure\ai\evaluation\_evaluate\_evaluate.py", line 855, in _evaluate
    studio_url = _log_metrics_and_instance_results(
                 ^^^^^^^^^^^^^^^^^^^^^^^^^^^^^^^^^^
  File "C:\Users\zhuohangli\Documents\dev\rag-ai-foundry-sdk-custom-chat-app\.venv\Lib\site-packages\azure\ai\evaluation\_evaluate\_utils.py", line 183, in _log_metrics_and_instance_results
    ev_run.log_artifact(tmpdir, artifact_name)
  File "C:\Users\zhuohangli\Documents\dev\rag-ai-foundry-sdk-custom-chat-app\.venv\Lib\site-packages\azure\ai\evaluation\_evaluate\_eval_run.py", line 451, in log_artifact
    raise EvaluationException(
azure.ai.evaluation._exceptions.EvaluationException: (UserError) Failed to upload evaluation run to the cloud due to insufficient permission to access the storage. Please ensure that the necessary access rights are granted.
Visit https://aka.ms/azsdk/python/evaluation/remotetracking/troubleshoot to troubleshoot this issue.